2019-03-11 11:45:57,197 - DEBUG - App.py[:23] - 启动websock,端口是:4397
2019-03-11 11:47:10,752 - DEBUG - App.py[:23] - 启动websock,端口是:4397
2019-03-11 11:49:23,001 - DEBUG - App.py[:23] - 启动websock,端口是:4397
2019-03-11 11:49:29,753 - ERROR - Service.py[:63] - recv data error exe con.close ,info:Traceback (most recent call last):
  File "/Users/tanjun/it/GitHub/cat08/cat08_websocket/cat08/Service.py", line 60, in run
    msg = self.branch(self.buffer_utf8)
  File "/Users/tanjun/it/GitHub/cat08/cat08_websocket/cat08/Service.py", line 73, in branch
    raise RuntimeError("client close")
RuntimeError: client close

2019-03-11 11:54:11,525 - DEBUG - App.py[:23] - 启动websock,端口是:4397
2019-03-11 11:55:28,306 - ERROR - Service.py[:63] - recv data error exe con.close ,info:Traceback (most recent call last):
  File "/Users/tanjun/it/GitHub/cat08/cat08_websocket/cat08/Service.py", line 60, in run
    msg = self.branch(self.buffer_utf8)
  File "/Users/tanjun/it/GitHub/cat08/cat08_websocket/cat08/Service.py", line 73, in branch
    raise RuntimeError("client close")
RuntimeError: client close

2019-03-11 11:55:31,037 - ERROR - Service.py[:63] - recv data error exe con.close ,info:Traceback (most recent call last):
  File "/Users/tanjun/it/GitHub/cat08/cat08_websocket/cat08/Service.py", line 60, in run
    msg = self.branch(self.buffer_utf8)
  File "/Users/tanjun/it/GitHub/cat08/cat08_websocket/cat08/Service.py", line 73, in branch
    raise RuntimeError("client close")
RuntimeError: client close

2019-03-11 13:45:48,398 - ERROR - Service.py[:63] - recv data error exe con.close ,info:Traceback (most recent call last):
  File "/Users/tanjun/it/GitHub/cat08/cat08_websocket/cat08/Service.py", line 52, in run
    raise RuntimeError("client close")
RuntimeError: client close

2019-03-11 13:45:48,406 - ERROR - Service.py[:63] - recv data error exe con.close ,info:Traceback (most recent call last):
  File "/Users/tanjun/it/GitHub/cat08/cat08_websocket/cat08/Service.py", line 52, in run
    raise RuntimeError("client close")
RuntimeError: client close

2019-03-11 13:49:58,523 - ERROR - Service.py[:63] - recv data error exe con.close ,info:Traceback (most recent call last):
  File "/Users/tanjun/it/GitHub/cat08/cat08_websocket/cat08/Service.py", line 60, in run
    msg = self.branch(self.buffer_utf8)
  File "/Users/tanjun/it/GitHub/cat08/cat08_websocket/cat08/Service.py", line 86, in branch
    self.branch(nextMsg)
  File "/Users/tanjun/it/GitHub/cat08/cat08_websocket/cat08/Service.py", line 73, in branch
    raise RuntimeError("client close")
RuntimeError: client close

2019-03-11 13:51:43,544 - ERROR - Service.py[:63] - recv data error exe con.close ,info:Traceback (most recent call last):
  File "/Users/tanjun/it/GitHub/cat08/cat08_websocket/cat08/Service.py", line 52, in run
    raise RuntimeError("client close")
RuntimeError: client close

2019-03-11 13:51:43,545 - ERROR - Service.py[:63] - recv data error exe con.close ,info:Traceback (most recent call last):
  File "/Users/tanjun/it/GitHub/cat08/cat08_websocket/cat08/Service.py", line 52, in run
    raise RuntimeError("client close")
RuntimeError: client close

2019-03-11 13:54:00,395 - ERROR - Service.py[:63] - recv data error exe con.close ,info:Traceback (most recent call last):
  File "/Users/tanjun/it/GitHub/cat08/cat08_websocket/cat08/Service.py", line 60, in run
    msg = self.branch(self.buffer_utf8)
  File "/Users/tanjun/it/GitHub/cat08/cat08_websocket/cat08/Service.py", line 86, in branch
    self.branch(nextMsg)
  File "/Users/tanjun/it/GitHub/cat08/cat08_websocket/cat08/Service.py", line 75, in branch
    msgSize = int(msg[0:5])
ValueError: invalid literal for int() with base 10: '\xaf\xbb00\x9e'

2019-03-11 13:58:44,458 - DEBUG - App.py[:23] - 启动websock,端口是:4397
2019-03-11 14:01:30,532 - ERROR - Service.py[:63] - recv data error exe con.close ,info:Traceback (most recent call last):
  File "/Users/tanjun/it/GitHub/cat08/cat08_websocket/cat08/Service.py", line 52, in run
    raise RuntimeError("client close")
RuntimeError: client close

2019-03-11 14:02:51,176 - ERROR - Service.py[:63] - recv data error exe con.close ,info:Traceback (most recent call last):
  File "/Users/tanjun/it/GitHub/cat08/cat08_websocket/cat08/Service.py", line 60, in run
    msg = self.branch(self.buffer_utf8)
  File "/Users/tanjun/it/GitHub/cat08/cat08_websocket/cat08/Service.py", line 86, in branch
    self.branch(nextMsg)
  File "/Users/tanjun/it/GitHub/cat08/cat08_websocket/cat08/Service.py", line 75, in branch
    msgSize = int(msg[0:5])
ValueError: invalid literal for int() with base 10: '\x87\x0800\xb6'

2019-03-11 14:03:21,248 - ERROR - Service.py[:63] - recv data error exe con.close ,info:Traceback (most recent call last):
  File "/Users/tanjun/it/GitHub/cat08/cat08_websocket/cat08/Service.py", line 60, in run
    msg = self.branch(self.buffer_utf8)
  File "/Users/tanjun/it/GitHub/cat08/cat08_websocket/cat08/Service.py", line 86, in branch
    self.branch(nextMsg)
  File "/Users/tanjun/it/GitHub/cat08/cat08_websocket/cat08/Service.py", line 75, in branch
    msgSize = int(msg[0:5])
ValueError: invalid literal for int() with base 10: '\xce800\xff'

2019-03-11 14:03:23,399 - ERROR - Service.py[:63] - recv data error exe con.close ,info:Traceback (most recent call last):
  File "/Users/tanjun/it/GitHub/cat08/cat08_websocket/cat08/Service.py", line 60, in run
    msg = self.branch(self.buffer_utf8)
  File "/Users/tanjun/it/GitHub/cat08/cat08_websocket/cat08/Service.py", line 73, in branch
    raise RuntimeError("client close")
RuntimeError: client close

2019-03-11 14:03:54,102 - ERROR - Service.py[:63] - recv data error exe con.close ,info:Traceback (most recent call last):
  File "/Users/tanjun/it/GitHub/cat08/cat08_websocket/cat08/Service.py", line 60, in run
    msg = self.branch(self.buffer_utf8)
  File "/Users/tanjun/it/GitHub/cat08/cat08_websocket/cat08/Service.py", line 73, in branch
    raise RuntimeError("client close")
RuntimeError: client close

2019-03-11 14:05:06,715 - ERROR - Service.py[:63] - recv data error exe con.close ,info:Traceback (most recent call last):
  File "/Users/tanjun/it/GitHub/cat08/cat08_websocket/cat08/Service.py", line 60, in run
    msg = self.branch(self.buffer_utf8)
  File "/Users/tanjun/it/GitHub/cat08/cat08_websocket/cat08/Service.py", line 84, in branch
    Util.senOthers(retMsg, self.con)
  File "/Users/tanjun/it/GitHub/cat08/cat08_websocket/cat08/Util.py", line 28, in senOthers
    con.sendall(msg)
  File "/System/Library/Frameworks/Python.framework/Versions/2.7/lib/python2.7/socket.py", line 228, in meth
    return getattr(self._sock,name)(*args)
error: [Errno 32] Broken pipe

2019-03-11 14:06:25,554 - ERROR - Service.py[:63] - recv data error exe con.close ,info:Traceback (most recent call last):
  File "/Users/tanjun/it/GitHub/cat08/cat08_websocket/cat08/Service.py", line 60, in run
    msg = self.branch(self.buffer_utf8)
  File "/Users/tanjun/it/GitHub/cat08/cat08_websocket/cat08/Service.py", line 86, in branch
    self.branch(nextMsg)
  File "/Users/tanjun/it/GitHub/cat08/cat08_websocket/cat08/Service.py", line 75, in branch
    msgSize = int(msg[0:5])
ValueError: invalid literal for int() with base 10: 'a\xdd00S'

2019-03-11 14:06:26,145 - ERROR - Service.py[:63] - recv data error exe con.close ,info:Traceback (most recent call last):
  File "/Users/tanjun/it/GitHub/cat08/cat08_websocket/cat08/Service.py", line 60, in run
    msg = self.branch(self.buffer_utf8)
  File "/Users/tanjun/it/GitHub/cat08/cat08_websocket/cat08/Service.py", line 86, in branch
    self.branch(nextMsg)
  File "/Users/tanjun/it/GitHub/cat08/cat08_websocket/cat08/Service.py", line 75, in branch
    msgSize = int(msg[0:5])
ValueError: invalid literal for int() with base 10: 'KQ00y'

2019-03-11 14:07:37,349 - DEBUG - App.py[:23] - 启动websock,端口是:4397
2019-03-11 14:09:00,379 - ERROR - Service.py[:63] - recv data error exe con.close ,info:Traceback (most recent call last):
  File "/Users/tanjun/it/GitHub/cat08/cat08_websocket/cat08/Service.py", line 60, in run
    msg = self.branch(self.buffer_utf8)
  File "/Users/tanjun/it/GitHub/cat08/cat08_websocket/cat08/Service.py", line 89, in branch
    self.branch(nextMsg)
  File "/Users/tanjun/it/GitHub/cat08/cat08_websocket/cat08/Service.py", line 82, in branch
    if len(msg) != msgSize:  # 如果两者不相等,基本上msg会大于msgSize,那就发生了沾包的情况,需要分开
UnboundLocalError: local variable 'msgSize' referenced before assignment

2019-03-11 14:10:29,736 - ERROR - Service.py[:63] - recv data error exe con.close ,info:Traceback (most recent call last):
  File "/Users/tanjun/it/GitHub/cat08/cat08_websocket/cat08/Service.py", line 52, in run
    raise RuntimeError("client close")
RuntimeError: client close

2019-03-11 14:11:19,996 - ERROR - Service.py[:63] - recv data error exe con.close ,info:Traceback (most recent call last):
  File "/Users/tanjun/it/GitHub/cat08/cat08_websocket/cat08/Service.py", line 60, in run
    msg = self.branch(self.buffer_utf8)
  File "/Users/tanjun/it/GitHub/cat08/cat08_websocket/cat08/Service.py", line 89, in branch
    self.branch(nextMsg)
  File "/Users/tanjun/it/GitHub/cat08/cat08_websocket/cat08/Service.py", line 82, in branch
    if len(msg) != msgSize:  # 如果两者不相等,基本上msg会大于msgSize,那就发生了沾包的情况,需要分开
UnboundLocalError: local variable 'msgSize' referenced before assignment

2019-03-11 14:11:48,788 - ERROR - Service.py[:63] - recv data error exe con.close ,info:Traceback (most recent call last):
  File "/Users/tanjun/it/GitHub/cat08/cat08_websocket/cat08/Service.py", line 60, in run
    msg = self.branch(self.buffer_utf8)
  File "/Users/tanjun/it/GitHub/cat08/cat08_websocket/cat08/Service.py", line 89, in branch
    self.branch(nextMsg)
  File "/Users/tanjun/it/GitHub/cat08/cat08_websocket/cat08/Service.py", line 82, in branch
    if len(msg) != msgSize:  # 如果两者不相等,基本上msg会大于msgSize,那就发生了沾包的情况,需要分开
UnboundLocalError: local variable 'msgSize' referenced before assignment

2019-03-11 14:11:48,794 - ERROR - Service.py[:63] - recv data error exe con.close ,info:Traceback (most recent call last):
  File "/Users/tanjun/it/GitHub/cat08/cat08_websocket/cat08/Service.py", line 60, in run
    msg = self.branch(self.buffer_utf8)
  File "/Users/tanjun/it/GitHub/cat08/cat08_websocket/cat08/Service.py", line 73, in branch
    raise RuntimeError("client close")
RuntimeError: client close

2019-03-11 14:13:02,987 - ERROR - Service.py[:63] - recv data error exe con.close ,info:Traceback (most recent call last):
  File "/Users/tanjun/it/GitHub/cat08/cat08_websocket/cat08/Service.py", line 60, in run
    msg = self.branch(self.buffer_utf8)
  File "/Users/tanjun/it/GitHub/cat08/cat08_websocket/cat08/Service.py", line 89, in branch
    self.branch(nextMsg)
  File "/Users/tanjun/it/GitHub/cat08/cat08_websocket/cat08/Service.py", line 82, in branch
    if len(msg) != msgSize:  # 如果两者不相等,基本上msg会大于msgSize,那就发生了沾包的情况,需要分开
UnboundLocalError: local variable 'msgSize' referenced before assignment

2019-03-11 14:13:03,514 - ERROR - Service.py[:63] - recv data error exe con.close ,info:Traceback (most recent call last):
  File "/Users/tanjun/it/GitHub/cat08/cat08_websocket/cat08/Service.py", line 60, in run
    msg = self.branch(self.buffer_utf8)
  File "/Users/tanjun/it/GitHub/cat08/cat08_websocket/cat08/Service.py", line 89, in branch
    self.branch(nextMsg)
  File "/Users/tanjun/it/GitHub/cat08/cat08_websocket/cat08/Service.py", line 82, in branch
    if len(msg) != msgSize:  # 如果两者不相等,基本上msg会大于msgSize,那就发生了沾包的情况,需要分开
UnboundLocalError: local variable 'msgSize' referenced before assignment

2019-03-11 14:17:38,479 - ERROR - Service.py[:63] - recv data error exe con.close ,info:Traceback (most recent call last):
  File "/Users/tanjun/it/GitHub/cat08/cat08_websocket/cat08/Service.py", line 60, in run
    msg = self.branch(self.buffer_utf8)
  File "/Users/tanjun/it/GitHub/cat08/cat08_websocket/cat08/Service.py", line 89, in branch
    self.branch(nextMsg)
  File "/Users/tanjun/it/GitHub/cat08/cat08_websocket/cat08/Service.py", line 82, in branch
    if len(msg) != msgSize:  # 如果两者不相等,基本上msg会大于msgSize,那就发生了沾包的情况,需要分开
UnboundLocalError: local variable 'msgSize' referenced before assignment

2019-03-11 14:17:38,485 - ERROR - Service.py[:63] - recv data error exe con.close ,info:Traceback (most recent call last):
  File "/Users/tanjun/it/GitHub/cat08/cat08_websocket/cat08/Service.py", line 60, in run
    msg = self.branch(self.buffer_utf8)
  File "/Users/tanjun/it/GitHub/cat08/cat08_websocket/cat08/Service.py", line 89, in branch
    self.branch(nextMsg)
  File "/Users/tanjun/it/GitHub/cat08/cat08_websocket/cat08/Service.py", line 82, in branch
    if len(msg) != msgSize:  # 如果两者不相等,基本上msg会大于msgSize,那就发生了沾包的情况,需要分开
UnboundLocalError: local variable 'msgSize' referenced before assignment

2019-03-11 14:18:22,122 - DEBUG - App.py[:23] - 启动websock,端口是:4397
2019-03-11 14:23:21,661 - ERROR - Service.py[:63] - recv data error exe con.close ,info:Traceback (most recent call last):
  File "/Users/tanjun/it/GitHub/cat08/cat08_websocket/cat08/Service.py", line 52, in run
    raise RuntimeError("client close")
RuntimeError: client close

2019-03-11 14:23:21,662 - ERROR - Service.py[:63] - recv data error exe con.close ,info:Traceback (most recent call last):
  File "/Users/tanjun/it/GitHub/cat08/cat08_websocket/cat08/Service.py", line 52, in run
    raise RuntimeError("client close")
RuntimeError: client close

2019-03-11 14:28:15,650 - ERROR - Service.py[:63] - recv data error exe con.close ,info:Traceback (most recent call last):
  File "/Users/tanjun/it/GitHub/cat08/cat08_websocket/cat08/Service.py", line 52, in run
    raise RuntimeError("client close")
RuntimeError: client close

2019-03-11 14:28:15,652 - ERROR - Service.py[:63] - recv data error exe con.close ,info:Traceback (most recent call last):
  File "/Users/tanjun/it/GitHub/cat08/cat08_websocket/cat08/Service.py", line 52, in run
    raise RuntimeError("client close")
RuntimeError: client close

2019-03-11 14:40:42,352 - DEBUG - App.py[:23] - 启动websock,端口是:4397
2019-03-11 14:41:54,952 - ERROR - Service.py[:63] - recv data error exe con.close ,info:Traceback (most recent call last):
  File "/Users/tanjun/it/GitHub/cat08/cat08_websocket/cat08/Service.py", line 52, in run
    raise RuntimeError("client close")
RuntimeError: client close

2019-03-11 14:43:12,565 - ERROR - Service.py[:63] - recv data error exe con.close ,info:Traceback (most recent call last):
  File "/Users/tanjun/it/GitHub/cat08/cat08_websocket/cat08/Service.py", line 52, in run
    raise RuntimeError("client close")
RuntimeError: client close

2019-03-11 14:43:36,455 - DEBUG - App.py[:23] - 启动websock,端口是:4397
2019-03-11 14:43:48,334 - ERROR - Service.py[:63] - recv data error exe con.close ,info:Traceback (most recent call last):
  File "/Users/tanjun/it/GitHub/cat08/cat08_websocket/cat08/Service.py", line 60, in run
    msg = self.branch(self.buffer_utf8)
  File "/Users/tanjun/it/GitHub/cat08/cat08_websocket/cat08/Service.py", line 73, in branch
    raise RuntimeError("client close")
RuntimeError: client close

2019-03-11 14:44:53,169 - ERROR - Service.py[:63] - recv data error exe con.close ,info:Traceback (most recent call last):
  File "/Users/tanjun/it/GitHub/cat08/cat08_websocket/cat08/Service.py", line 52, in run
    raise RuntimeError("client close")
RuntimeError: client close

2019-03-11 14:45:48,342 - DEBUG - App.py[:23] - 启动websock,端口是:4397
2019-03-11 14:50:37,252 - ERROR - Service.py[:63] - recv data error exe con.close ,info:Traceback (most recent call last):
  File "/Users/tanjun/it/GitHub/cat08/cat08_websocket/cat08/Service.py", line 60, in run
    msg = self.branch(self.buffer_utf8)
  File "/Users/tanjun/it/GitHub/cat08/cat08_websocket/cat08/Service.py", line 90, in branch
    self.branch(nextMsg)
  File "/Users/tanjun/it/GitHub/cat08/cat08_websocket/cat08/Service.py", line 83, in branch
    if len(msg) != msgSize:  # 如果两者不相等,基本上msg会大于msgSize,那就发生了沾包的情况,需要分开
UnboundLocalError: local variable 'msgSize' referenced before assignment

2019-03-11 15:33:58,754 - DEBUG - App.py[:23] - 启动websock,端口是:4397
2019-03-11 15:42:08,517 - ERROR - Service.py[:63] - recv data error exe con.close ,info:Traceback (most recent call last):
  File "/Users/tanjun/it/GitHub/cat08/cat08_websocket/cat08/Service.py", line 60, in run
    msg = self.branch(self.buffer_utf8)
  File "/Users/tanjun/it/GitHub/cat08/cat08_websocket/cat08/Service.py", line 90, in branch
    self.branch(nextMsg)
  File "/Users/tanjun/it/GitHub/cat08/cat08_websocket/cat08/Service.py", line 83, in branch
    if len(msg) != msgSize:  # 如果两者不相等,基本上msg会大于msgSize,那就发生了沾包的情况,需要分开
UnboundLocalError: local variable 'msgSize' referenced before assignment

2019-03-11 15:43:20,100 - DEBUG - App.py[:23] - 启动websock,端口是:4397
2019-03-11 15:44:31,014 - DEBUG - App.py[:23] - 启动websock,端口是:4397
2019-03-11 15:45:05,887 - ERROR - Service.py[:63] - recv data error exe con.close ,info:Traceback (most recent call last):
  File "/Users/tanjun/it/GitHub/cat08/cat08_websocket/cat08/Service.py", line 60, in run
    msg = self.branch(self.buffer_utf8)
  File "/Users/tanjun/it/GitHub/cat08/cat08_websocket/cat08/Service.py", line 91, in branch
    self.branch(nextMsg)
  File "/Users/tanjun/it/GitHub/cat08/cat08_websocket/cat08/Service.py", line 74, in branch
    raise RuntimeError("client close")
RuntimeError: client close

2019-03-11 15:45:06,330 - ERROR - Service.py[:63] - recv data error exe con.close ,info:Traceback (most recent call last):
  File "/Users/tanjun/it/GitHub/cat08/cat08_websocket/cat08/Service.py", line 60, in run
    msg = self.branch(self.buffer_utf8)
  File "/Users/tanjun/it/GitHub/cat08/cat08_websocket/cat08/Service.py", line 91, in branch
    self.branch(nextMsg)
  File "/Users/tanjun/it/GitHub/cat08/cat08_websocket/cat08/Service.py", line 84, in branch
    if len(msg) != msgSize:  # 如果两者不相等,基本上msg会大于msgSize,那就发生了沾包的情况,需要分开
UnboundLocalError: local variable 'msgSize' referenced before assignment

2019-03-11 15:50:48,958 - DEBUG - App.py[:23] - 启动websock,端口是:4397
2019-03-11 15:50:54,120 - ERROR - Service.py[:63] - recv data error exe con.close ,info:Traceback (most recent call last):
  File "/Users/tanjun/it/GitHub/cat08/cat08_websocket/cat08/Service.py", line 60, in run
    msg = self.branch(self.buffer_utf8)
  File "/Users/tanjun/it/GitHub/cat08/cat08_websocket/cat08/Service.py", line 72, in branch
    print("之前长度" + len(msg))
TypeError: cannot concatenate 'str' and 'int' objects

2019-03-11 15:51:36,633 - DEBUG - App.py[:23] - 启动websock,端口是:4397
2019-03-11 15:56:43,625 - DEBUG - App.py[:23] - 启动websock,端口是:4397
2019-03-11 15:58:14,163 - DEBUG - App.py[:23] - 启动websock,端口是:4397
2019-03-11 16:30:48,456 - DEBUG - App.py[:23] - 启动websock,端口是:4397
2019-03-11 16:31:25,308 - ERROR - Service.py[:68] - recv data error exe con.close ,info:Traceback (most recent call last):
  File "/Users/tanjun/it/GitHub/cat08/cat08_websocket/cat08/Service.py", line 53, in run
    msg = Util.t_recvStr(msg)
  File "/Users/tanjun/it/GitHub/cat08/cat08_websocket/cat08/Util.py", line 64, in t_recvStr
    payload_len = ord(info[1]) & 127 #126以内是正确的长度
IndexError: string index out of range

2019-03-11 16:33:37,089 - DEBUG - App.py[:23] - 启动websock,端口是:4397
2019-03-11 16:36:02,731 - DEBUG - App.py[:23] - 启动websock,端口是:4397
2019-03-11 16:51:33,327 - DEBUG - App.py[:23] - 启动websock,端口是:4397
2019-03-11 16:51:45,809 - ERROR - Service.py[:66] - recv data error exe con.close ,info:Traceback (most recent call last):
  File "/Users/tanjun/it/GitHub/cat08/cat08_websocket/cat08/Service.py", line 60, in run
    print("max = " + len(msg))
TypeError: cannot concatenate 'str' and 'int' objects

2019-03-11 16:51:46,574 - ERROR - Service.py[:66] - recv data error exe con.close ,info:Traceback (most recent call last):
  File "/Users/tanjun/it/GitHub/cat08/cat08_websocket/cat08/Service.py", line 60, in run
    print("max = " + len(msg))
TypeError: cannot concatenate 'str' and 'int' objects

2019-03-11 16:51:47,249 - ERROR - Service.py[:66] - recv data error exe con.close ,info:Traceback (most recent call last):
  File "/Users/tanjun/it/GitHub/cat08/cat08_websocket/cat08/Service.py", line 60, in run
    print("max = " + len(msg))
TypeError: cannot concatenate 'str' and 'int' objects

2019-03-11 16:51:47,458 - ERROR - Service.py[:66] - recv data error exe con.close ,info:Traceback (most recent call last):
  File "/Users/tanjun/it/GitHub/cat08/cat08_websocket/cat08/Service.py", line 60, in run
    print("max = " + len(msg))
TypeError: cannot concatenate 'str' and 'int' objects

2019-03-11 16:52:23,765 - DEBUG - App.py[:23] - 启动websock,端口是:4397
2019-03-11 16:52:28,796 - ERROR - Service.py[:66] - recv data error exe con.close ,info:Traceback (most recent call last):
  File "/Users/tanjun/it/GitHub/cat08/cat08_websocket/cat08/Service.py", line 61, in run
    print("g_header_length = " + str(g_header_length))
NameError: global name 'g_header_length' is not defined

2019-03-11 16:53:58,771 - DEBUG - App.py[:23] - 启动websock,端口是:4397
2019-03-11 17:04:59,485 - DEBUG - App.py[:23] - 启动websock,端口是:4397
2019-03-11 17:06:12,413 - DEBUG - App.py[:23] - 启动websock,端口是:4397
2019-03-11 17:07:27,405 - DEBUG - App.py[:23] - 启动websock,端口是:4397
2019-03-11 17:08:20,451 - DEBUG - App.py[:23] - 启动websock,端口是:4397
2019-03-11 17:08:49,432 - ERROR - Service.py[:72] - recv data error exe con.close ,info:Traceback (most recent call last):
  File "/Users/tanjun/it/GitHub/cat08/cat08_websocket/cat08/Service.py", line 45, in run
    raise KeyError("websocket key error:" + str(e.message))
KeyError: 'websocket key error:Sec-WebSocket-Protocol'

2019-03-11 17:10:01,622 - ERROR - Service.py[:72] - recv data error exe con.close ,info:Traceback (most recent call last):
  File "/Users/tanjun/it/GitHub/cat08/cat08_websocket/cat08/Service.py", line 68, in run
    print(Util.t_recvStr(msg[self.g_header_length:(self.g_header_length + self.g_code_length)]))
  File "/Users/tanjun/it/GitHub/cat08/cat08_websocket/cat08/Util.py", line 65, in t_recvStr
    payload_len = ord(info[1]) & 127 #126以内是正确的长度
IndexError: string index out of range

2019-03-11 17:12:08,708 - DEBUG - App.py[:23] - 启动websock,端口是:4397
2019-03-11 17:12:45,797 - ERROR - Service.py[:63] - recv data error exe con.close ,info:Traceback (most recent call last):
  File "/Users/tanjun/it/GitHub/cat08/cat08_websocket/cat08/Service.py", line 60, in run
    msg = self.branch(self.buffer_utf8)
  File "/Users/tanjun/it/GitHub/cat08/cat08_websocket/cat08/Service.py", line 86, in branch
    self.branch(nextMsg)
  File "/Users/tanjun/it/GitHub/cat08/cat08_websocket/cat08/Service.py", line 73, in branch
    raise RuntimeError("client close")
RuntimeError: client close

2019-03-11 17:14:07,713 - ERROR - Service.py[:63] - recv data error exe con.close ,info:Traceback (most recent call last):
  File "/Users/tanjun/it/GitHub/cat08/cat08_websocket/cat08/Service.py", line 60, in run
    msg = self.branch(self.buffer_utf8)
  File "/Users/tanjun/it/GitHub/cat08/cat08_websocket/cat08/Service.py", line 86, in branch
    self.branch(nextMsg)
  File "/Users/tanjun/it/GitHub/cat08/cat08_websocket/cat08/Service.py", line 75, in branch
    msgSize = int(msg[0:5])
ValueError: invalid literal for int() with base 10: '\xa1/00\x90'

2019-03-11 17:15:05,585 - DEBUG - App.py[:23] - 启动websock,端口是:4397
2019-03-11 17:16:19,555 - DEBUG - App.py[:23] - 启动websock,端口是:4397
2019-03-11 17:17:26,481 - ERROR - Service.py[:62] - recv data error exe con.close ,info:Traceback (most recent call last):
  File "/Users/tanjun/it/GitHub/cat08/cat08_websocket/cat08/Service.py", line 59, in run
    msg = self.branch(self.buffer_utf8)
  File "/Users/tanjun/it/GitHub/cat08/cat08_websocket/cat08/Service.py", line 85, in branch
    self.branch(nextMsg)
  File "/Users/tanjun/it/GitHub/cat08/cat08_websocket/cat08/Service.py", line 74, in branch
    msgSize = int(msg[0:5])
ValueError: invalid literal for int() with base 10: '\xb8\r00\x89'

2019-03-11 17:18:30,914 - ERROR - Service.py[:62] - recv data error exe con.close ,info:Traceback (most recent call last):
  File "/Users/tanjun/it/GitHub/cat08/cat08_websocket/cat08/Service.py", line 59, in run
    msg = self.branch(self.buffer_utf8)
  File "/Users/tanjun/it/GitHub/cat08/cat08_websocket/cat08/Service.py", line 85, in branch
    self.branch(nextMsg)
  File "/Users/tanjun/it/GitHub/cat08/cat08_websocket/cat08/Service.py", line 74, in branch
    msgSize = int(msg[0:5])
ValueError: invalid literal for int() with base 10: 'd\xbe00U'

2019-03-11 17:19:44,883 - DEBUG - App.py[:23] - 启动websock,端口是:4397
2019-03-11 17:20:21,311 - ERROR - Service.py[:62] - recv data error exe con.close ,info:Traceback (most recent call last):
  File "/Users/tanjun/it/GitHub/cat08/cat08_websocket/cat08/Service.py", line 59, in run
    msg = self.branch(self.buffer_utf8)
  File "/Users/tanjun/it/GitHub/cat08/cat08_websocket/cat08/Service.py", line 87, in branch
    self.branch(nextMsg)
  File "/Users/tanjun/it/GitHub/cat08/cat08_websocket/cat08/Service.py", line 76, in branch
    msgSize = int(msg[0:5])
ValueError: invalid literal for int() with base 10: '\xcc\x9300\xfd'

2019-03-11 17:23:47,897 - DEBUG - App.py[:23] - 启动websock,端口是:4397
2019-03-11 17:27:19,611 - DEBUG - App.py[:23] - 启动websock,端口是:4397
2019-03-11 17:33:03,668 - DEBUG - App.py[:23] - 启动websock,端口是:4397
2019-03-11 17:35:28,894 - DEBUG - App.py[:23] - 启动websock,端口是:4397
2019-03-11 17:38:36,966 - DEBUG - App.py[:23] - 启动websock,端口是:4397
2019-03-11 17:38:41,196 - ERROR - Service.py[:66] - recv data error exe con.close ,info:Traceback (most recent call last):
  File "/Users/tanjun/it/GitHub/cat08/cat08_websocket/cat08/Service.py", line 62, in run
    print(int(msglen))
ValueError: invalid literal for int() with base 10: '\xcb\x9e\x0cQ\xcb'

2019-03-11 17:38:42,964 - ERROR - Service.py[:66] - recv data error exe con.close ,info:Traceback (most recent call last):
  File "/Users/tanjun/it/GitHub/cat08/cat08_websocket/cat08/Service.py", line 62, in run
    print(int(msglen))
ValueError: invalid literal for int() with base 10: '%\x0f\xe4\x19%'

2019-03-11 17:39:17,454 - DEBUG - App.py[:23] - 启动websock,端口是:4397
2019-03-11 17:40:16,333 - DEBUG - App.py[:23] - 启动websock,端口是:4397
2019-03-11 17:40:40,398 - ERROR - Service.py[:67] - recv data error exe con.close ,info:Traceback (most recent call last):
  File "/Users/tanjun/it/GitHub/cat08/cat08_websocket/cat08/Service.py", line 63, in run
    print(int(msglen))
ValueError: invalid literal for int() with base 10: ''

2019-03-11 17:42:21,279 - DEBUG - App.py[:23] - 启动websock,端口是:4397
2019-03-11 18:00:55,069 - DEBUG - App.py[:23] - 启动websock,端口是:4397
2019-03-11 18:02:37,930 - DEBUG - App.py[:23] - 启动websock,端口是:4397
2019-03-11 18:04:17,288 - ERROR - Service.py[:62] - recv data error exe con.close ,info:Traceback (most recent call last):
  File "/Users/tanjun/it/GitHub/cat08/cat08_websocket/cat08/Service.py", line 59, in run
    msg = self.branch(self.buffer_utf8)
  File "/Users/tanjun/it/GitHub/cat08/cat08_websocket/cat08/Service.py", line 86, in branch
    self.branch(nextMsg)
  File "/Users/tanjun/it/GitHub/cat08/cat08_websocket/cat08/Service.py", line 71, in branch
    headlen = Util.t_headerlen(self.buffer_utf8)
  File "/Users/tanjun/it/GitHub/cat08/cat08_websocket/cat08/Util.py", line 65, in t_headerlen
    payload_len = ord(info[1]) & 127  # 126以内是正确的长度
IndexError: string index out of range

2019-03-11 18:20:45,757 - DEBUG - App.py[:23] - 启动websock,端口是:4397
2019-03-11 18:21:46,247 - ERROR - Service.py[:68] - recv data error exe con.close ,info:Traceback (most recent call last):
  File "/Users/tanjun/it/GitHub/cat08/cat08_websocket/cat08/Service.py", line 64, in run
    msg = self.branch(msg)
  File "/Users/tanjun/it/GitHub/cat08/cat08_websocket/cat08/Service.py", line 90, in branch
    self.branch(nextMsg)
  File "/Users/tanjun/it/GitHub/cat08/cat08_websocket/cat08/Service.py", line 78, in branch
    msglen = int(Util.t_recvStr(self.mask,msglen))
ValueError: invalid literal for int() with base 10: '\xe8\x81y1\xfe'

2019-03-11 18:23:21,525 - ERROR - Service.py[:68] - recv data error exe con.close ,info:Traceback (most recent call last):
  File "/Users/tanjun/it/GitHub/cat08/cat08_websocket/cat08/Service.py", line 64, in run
    msg = self.branch(msg)
  File "/Users/tanjun/it/GitHub/cat08/cat08_websocket/cat08/Service.py", line 90, in branch
    self.branch(nextMsg)
  File "/Users/tanjun/it/GitHub/cat08/cat08_websocket/cat08/Service.py", line 78, in branch
    msglen = int(Util.t_recvStr(self.mask,msglen))
ValueError: invalid literal for int() with base 10: '\xc9\x1f\x16x\xa4'

2019-03-11 18:24:15,168 - DEBUG - App.py[:23] - 启动websock,端口是:4397
2019-03-11 18:26:14,375 - ERROR - Service.py[:68] - recv data error exe con.close ,info:Traceback (most recent call last):
  File "/Users/tanjun/it/GitHub/cat08/cat08_websocket/cat08/Service.py", line 64, in run
    msg = self.branch(msg)
  File "/Users/tanjun/it/GitHub/cat08/cat08_websocket/cat08/Service.py", line 90, in branch
    self.branch(nextMsg)
  File "/Users/tanjun/it/GitHub/cat08/cat08_websocket/cat08/Service.py", line 78, in branch
    msglen = int(Util.t_recvStr(self.mask,msglen))
ValueError: invalid literal for int() with base 10: 'L\x96\xe2\xed\xaf'

2019-03-11 18:27:21,532 - DEBUG - App.py[:23] - 启动websock,端口是:4397
2019-03-11 18:28:41,921 - ERROR - Service.py[:68] - recv data error exe con.close ,info:Traceback (most recent call last):
  File "/Users/tanjun/it/GitHub/cat08/cat08_websocket/cat08/Service.py", line 64, in run
    msg = self.branch(msg)
  File "/Users/tanjun/it/GitHub/cat08/cat08_websocket/cat08/Service.py", line 90, in branch
    self.branch(nextMsg)
  File "/Users/tanjun/it/GitHub/cat08/cat08_websocket/cat08/Service.py", line 78, in branch
    msglen = int(Util.t_recvStr(self.mask,msglen))
ValueError: invalid literal for int() with base 10: '\xad7Gz\x0f'

2019-03-11 18:28:43,326 - ERROR - Service.py[:68] - recv data error exe con.close ,info:Traceback (most recent call last):
  File "/Users/tanjun/it/GitHub/cat08/cat08_websocket/cat08/Service.py", line 64, in run
    msg = self.branch(msg)
  File "/Users/tanjun/it/GitHub/cat08/cat08_websocket/cat08/Service.py", line 90, in branch
    self.branch(nextMsg)
  File "/Users/tanjun/it/GitHub/cat08/cat08_websocket/cat08/Service.py", line 78, in branch
    msglen = int(Util.t_recvStr(self.mask,msglen))
ValueError: invalid literal for int() with base 10: '.ak\xb8}'

2019-03-11 18:30:39,939 - DEBUG - App.py[:23] - 启动websock,端口是:4397
2019-03-11 18:31:43,053 - ERROR - Service.py[:68] - recv data error exe con.close ,info:Traceback (most recent call last):
  File "/Users/tanjun/it/GitHub/cat08/cat08_websocket/cat08/Service.py", line 64, in run
    msg = self.branch(msg)
  File "/Users/tanjun/it/GitHub/cat08/cat08_websocket/cat08/Service.py", line 90, in branch
    self.branch(nextMsg)
  File "/Users/tanjun/it/GitHub/cat08/cat08_websocket/cat08/Service.py", line 78, in branch
    msglen = int(Util.t_recvStr(self.mask,msglen))
ValueError: invalid literal for int() with base 10: '6\x7fs+\x11'

2019-03-11 18:31:44,319 - ERROR - Service.py[:68] - recv data error exe con.close ,info:Traceback (most recent call last):
  File "/Users/tanjun/it/GitHub/cat08/cat08_websocket/cat08/Service.py", line 64, in run
    msg = self.branch(msg)
  File "/Users/tanjun/it/GitHub/cat08/cat08_websocket/cat08/Service.py", line 90, in branch
    self.branch(nextMsg)
  File "/Users/tanjun/it/GitHub/cat08/cat08_websocket/cat08/Service.py", line 78, in branch
    msglen = int(Util.t_recvStr(self.mask,msglen))
ValueError: invalid literal for int() with base 10: 'k\xbd\x8f\xa2'

2019-03-11 18:32:25,594 - DEBUG - App.py[:23] - 启动websock,端口是:4397
2019-03-11 18:33:08,658 - ERROR - Service.py[:68] - recv data error exe con.close ,info:Traceback (most recent call last):
  File "/Users/tanjun/it/GitHub/cat08/cat08_websocket/cat08/Service.py", line 64, in run
    msg = self.branch(msg)
  File "/Users/tanjun/it/GitHub/cat08/cat08_websocket/cat08/Service.py", line 93, in branch
    self.branch(nextMsg)
  File "/Users/tanjun/it/GitHub/cat08/cat08_websocket/cat08/Service.py", line 82, in branch
    tslen = 5 + 1 + msglen #业务协议长度+操作符+内容长度本次内容长度
TypeError: unsupported operand type(s) for +: 'int' and 'str'

2019-03-11 18:33:11,621 - ERROR - Service.py[:68] - recv data error exe con.close ,info:Traceback (most recent call last):
  File "/Users/tanjun/it/GitHub/cat08/cat08_websocket/cat08/Service.py", line 64, in run
    msg = self.branch(msg)
  File "/Users/tanjun/it/GitHub/cat08/cat08_websocket/cat08/Service.py", line 93, in branch
    self.branch(nextMsg)
  File "/Users/tanjun/it/GitHub/cat08/cat08_websocket/cat08/Service.py", line 82, in branch
    tslen = 5 + 1 + msglen #业务协议长度+操作符+内容长度本次内容长度
TypeError: unsupported operand type(s) for +: 'int' and 'str'

2019-03-11 18:33:51,723 - DEBUG - App.py[:23] - 启动websock,端口是:4397
2019-03-11 18:34:31,954 - ERROR - Service.py[:68] - recv data error exe con.close ,info:Traceback (most recent call last):
  File "/Users/tanjun/it/GitHub/cat08/cat08_websocket/cat08/Service.py", line 64, in run
    msg = self.branch(msg)
  File "/Users/tanjun/it/GitHub/cat08/cat08_websocket/cat08/Service.py", line 87, in branch
    raise RuntimeError("client close")
RuntimeError: client close

2019-03-11 18:35:27,597 - DEBUG - App.py[:23] - 启动websock,端口是:4397
2019-03-11 18:37:04,778 - DEBUG - App.py[:23] - 启动websock,端口是:4397
2019-03-11 18:37:44,869 - ERROR - Service.py[:68] - recv data error exe con.close ,info:Traceback (most recent call last):
  File "/Users/tanjun/it/GitHub/cat08/cat08_websocket/cat08/Service.py", line 64, in run
    msg = self.branch(msg)
  File "/Users/tanjun/it/GitHub/cat08/cat08_websocket/cat08/Service.py", line 87, in branch
    raise RuntimeError("client close")
RuntimeError: client close

2019-03-11 18:38:13,467 - ERROR - Service.py[:68] - recv data error exe con.close ,info:Traceback (most recent call last):
  File "/Users/tanjun/it/GitHub/cat08/cat08_websocket/cat08/Service.py", line 64, in run
    msg = self.branch(msg)
  File "/Users/tanjun/it/GitHub/cat08/cat08_websocket/cat08/Service.py", line 87, in branch
    raise RuntimeError("client close")
RuntimeError: client close

2019-03-11 18:39:02,045 - ERROR - Service.py[:68] - recv data error exe con.close ,info:Traceback (most recent call last):
  File "/Users/tanjun/it/GitHub/cat08/cat08_websocket/cat08/Service.py", line 64, in run
    msg = self.branch(msg)
  File "/Users/tanjun/it/GitHub/cat08/cat08_websocket/cat08/Service.py", line 87, in branch
    raise RuntimeError("client close")
RuntimeError: client close

2019-03-11 18:39:37,092 - DEBUG - App.py[:23] - 启动websock,端口是:4397
2019-03-11 18:42:25,495 - ERROR - Service.py[:68] - recv data error exe con.close ,info:Traceback (most recent call last):
  File "/Users/tanjun/it/GitHub/cat08/cat08_websocket/cat08/Service.py", line 64, in run
    msg = self.branch(msg)
  File "/Users/tanjun/it/GitHub/cat08/cat08_websocket/cat08/Service.py", line 87, in branch
    raise RuntimeError("client close")
RuntimeError: client close

2019-03-11 18:43:07,263 - DEBUG - App.py[:23] - 启动websock,端口是:4397
2019-03-11 18:49:00,827 - DEBUG - App.py[:23] - 启动websock,端口是:4397
2019-03-11 18:50:32,227 - DEBUG - App.py[:23] - 启动websock,端口是:4397
2019-03-11 18:51:00,084 - ERROR - Service.py[:62] - recv data error exe con.close ,info:Traceback (most recent call last):
  File "/Users/tanjun/it/GitHub/cat08/cat08_websocket/cat08/Service.py", line 59, in run
    msg = self.branch(self.buffer_utf8)
  File "/Users/tanjun/it/GitHub/cat08/cat08_websocket/cat08/Service.py", line 72, in branch
    raise RuntimeError("client close")
RuntimeError: client close

2019-03-11 18:52:01,898 - ERROR - Service.py[:62] - recv data error exe con.close ,info:Traceback (most recent call last):
  File "/Users/tanjun/it/GitHub/cat08/cat08_websocket/cat08/Service.py", line 59, in run
    msg = self.branch(self.buffer_utf8)
  File "/Users/tanjun/it/GitHub/cat08/cat08_websocket/cat08/Service.py", line 85, in branch
    self.branch(nextMsg)
  File "/Users/tanjun/it/GitHub/cat08/cat08_websocket/cat08/Service.py", line 74, in branch
    msgSize = int(msg[0:5])
ValueError: invalid literal for int() with base 10: ';\x8400\n'

2019-03-11 18:52:16,017 - ERROR - Service.py[:62] - recv data error exe con.close ,info:Traceback (most recent call last):
  File "/Users/tanjun/it/GitHub/cat08/cat08_websocket/cat08/Service.py", line 59, in run
    msg = self.branch(self.buffer_utf8)
  File "/Users/tanjun/it/GitHub/cat08/cat08_websocket/cat08/Service.py", line 85, in branch
    self.branch(nextMsg)
  File "/Users/tanjun/it/GitHub/cat08/cat08_websocket/cat08/Service.py", line 74, in branch
    msgSize = int(msg[0:5])
ValueError: invalid literal for int() with base 10: '-\xcb00\x1c'

2019-03-11 18:52:31,464 - ERROR - Service.py[:62] - recv data error exe con.close ,info:Traceback (most recent call last):
  File "/Users/tanjun/it/GitHub/cat08/cat08_websocket/cat08/Service.py", line 59, in run
    msg = self.branch(self.buffer_utf8)
  File "/Users/tanjun/it/GitHub/cat08/cat08_websocket/cat08/Service.py", line 85, in branch
    self.branch(nextMsg)
  File "/Users/tanjun/it/GitHub/cat08/cat08_websocket/cat08/Service.py", line 74, in branch
    msgSize = int(msg[0:5])
ValueError: invalid literal for int() with base 10: '\xda\x1800\xeb'

2019-03-11 18:53:11,595 - ERROR - Service.py[:62] - recv data error exe con.close ,info:Traceback (most recent call last):
  File "/Users/tanjun/it/GitHub/cat08/cat08_websocket/cat08/Service.py", line 59, in run
    msg = self.branch(self.buffer_utf8)
  File "/Users/tanjun/it/GitHub/cat08/cat08_websocket/cat08/Service.py", line 85, in branch
    self.branch(nextMsg)
  File "/Users/tanjun/it/GitHub/cat08/cat08_websocket/cat08/Service.py", line 74, in branch
    msgSize = int(msg[0:5])
ValueError: invalid literal for int() with base 10: '\xd1\xcb00\xe0'

2019-03-11 18:53:25,995 - ERROR - Service.py[:62] - recv data error exe con.close ,info:Traceback (most recent call last):
  File "/Users/tanjun/it/GitHub/cat08/cat08_websocket/cat08/Service.py", line 59, in run
    msg = self.branch(self.buffer_utf8)
  File "/Users/tanjun/it/GitHub/cat08/cat08_websocket/cat08/Service.py", line 72, in branch
    raise RuntimeError("client close")
RuntimeError: client close

2019-03-11 18:53:37,569 - ERROR - Service.py[:62] - recv data error exe con.close ,info:Traceback (most recent call last):
  File "/Users/tanjun/it/GitHub/cat08/cat08_websocket/cat08/Service.py", line 59, in run
    msg = self.branch(self.buffer_utf8)
  File "/Users/tanjun/it/GitHub/cat08/cat08_websocket/cat08/Service.py", line 85, in branch
    self.branch(nextMsg)
  File "/Users/tanjun/it/GitHub/cat08/cat08_websocket/cat08/Service.py", line 74, in branch
    msgSize = int(msg[0:5])
ValueError: invalid literal for int() with base 10: 'E\xb500t'

2019-03-11 18:54:00,730 - ERROR - Service.py[:62] - recv data error exe con.close ,info:Traceback (most recent call last):
  File "/Users/tanjun/it/GitHub/cat08/cat08_websocket/cat08/Service.py", line 59, in run
    msg = self.branch(self.buffer_utf8)
  File "/Users/tanjun/it/GitHub/cat08/cat08_websocket/cat08/Service.py", line 85, in branch
    self.branch(nextMsg)
  File "/Users/tanjun/it/GitHub/cat08/cat08_websocket/cat08/Service.py", line 74, in branch
    msgSize = int(msg[0:5])
ValueError: invalid literal for int() with base 10: 'uk00D'

2019-03-11 18:54:36,610 - DEBUG - App.py[:23] - 启动websock,端口是:4397
2019-03-11 18:56:54,729 - ERROR - Service.py[:62] - recv data error exe con.close ,info:Traceback (most recent call last):
  File "/Users/tanjun/it/GitHub/cat08/cat08_websocket/cat08/Service.py", line 59, in run
    msg = self.branch(self.buffer_utf8)
  File "/Users/tanjun/it/GitHub/cat08/cat08_websocket/cat08/Service.py", line 85, in branch
    self.branch(nextMsg)
  File "/Users/tanjun/it/GitHub/cat08/cat08_websocket/cat08/Service.py", line 74, in branch
    msgSize = int(msg[0:5])
ValueError: invalid literal for int() with base 10: 'p\xec00A'

2019-03-11 18:57:33,024 - DEBUG - App.py[:23] - 启动websock,端口是:4397
2019-03-11 18:57:45,845 - ERROR - Service.py[:62] - recv data error exe con.close ,info:Traceback (most recent call last):
  File "/Users/tanjun/it/GitHub/cat08/cat08_websocket/cat08/Service.py", line 59, in run
    msg = self.branch(self.buffer_utf8)
  File "/Users/tanjun/it/GitHub/cat08/cat08_websocket/cat08/Service.py", line 72, in branch
    raise RuntimeError("client close")
RuntimeError: client close

2019-03-11 18:58:35,892 - ERROR - Service.py[:62] - recv data error exe con.close ,info:Traceback (most recent call last):
  File "/Users/tanjun/it/GitHub/cat08/cat08_websocket/cat08/Service.py", line 59, in run
    msg = self.branch(self.buffer_utf8)
  File "/Users/tanjun/it/GitHub/cat08/cat08_websocket/cat08/Service.py", line 85, in branch
    self.branch(nextMsg)
  File "/Users/tanjun/it/GitHub/cat08/cat08_websocket/cat08/Service.py", line 72, in branch
    raise RuntimeError("client close")
RuntimeError: client close

2019-03-11 18:58:51,732 - ERROR - Service.py[:62] - recv data error exe con.close ,info:Traceback (most recent call last):
  File "/Users/tanjun/it/GitHub/cat08/cat08_websocket/cat08/Service.py", line 59, in run
    msg = self.branch(self.buffer_utf8)
  File "/Users/tanjun/it/GitHub/cat08/cat08_websocket/cat08/Service.py", line 85, in branch
    self.branch(nextMsg)
  File "/Users/tanjun/it/GitHub/cat08/cat08_websocket/cat08/Service.py", line 74, in branch
    msgSize = int(msg[0:5])
ValueError: invalid literal for int() with base 10: '#\xb200\x12'

2019-03-11 19:00:35,769 - DEBUG - App.py[:23] - 启动websock,端口是:4397
2019-03-11 19:00:50,933 - ERROR - Service.py[:63] - recv data error exe con.close ,info:Traceback (most recent call last):
  File "/Users/tanjun/it/GitHub/cat08/cat08_websocket/cat08/Service.py", line 59, in run
    msg = self.branch(self.buffer_utf8)
  File "/Users/tanjun/it/GitHub/cat08/cat08_websocket/cat08/Service.py", line 73, in branch
    raise RuntimeError("client close")
RuntimeError: client close

2019-03-11 19:01:13,502 - ERROR - Service.py[:63] - recv data error exe con.close ,info:Traceback (most recent call last):
  File "/Users/tanjun/it/GitHub/cat08/cat08_websocket/cat08/Service.py", line 59, in run
    msg = self.branch(self.buffer_utf8)
  File "/Users/tanjun/it/GitHub/cat08/cat08_websocket/cat08/Service.py", line 73, in branch
    raise RuntimeError("client close")
RuntimeError: client close

2019-03-11 19:01:24,702 - ERROR - Service.py[:63] - recv data error exe con.close ,info:Traceback (most recent call last):
  File "/Users/tanjun/it/GitHub/cat08/cat08_websocket/cat08/Service.py", line 59, in run
    msg = self.branch(self.buffer_utf8)
  File "/Users/tanjun/it/GitHub/cat08/cat08_websocket/cat08/Service.py", line 73, in branch
    raise RuntimeError("client close")
RuntimeError: client close

2019-03-11 19:01:42,116 - ERROR - Service.py[:63] - recv data error exe con.close ,info:Traceback (most recent call last):
  File "/Users/tanjun/it/GitHub/cat08/cat08_websocket/cat08/Service.py", line 59, in run
    msg = self.branch(self.buffer_utf8)
  File "/Users/tanjun/it/GitHub/cat08/cat08_websocket/cat08/Service.py", line 73, in branch
    raise RuntimeError("client close")
RuntimeError: client close

2019-03-11 19:01:53,930 - ERROR - Service.py[:63] - recv data error exe con.close ,info:Traceback (most recent call last):
  File "/Users/tanjun/it/GitHub/cat08/cat08_websocket/cat08/Service.py", line 59, in run
    msg = self.branch(self.buffer_utf8)
  File "/Users/tanjun/it/GitHub/cat08/cat08_websocket/cat08/Service.py", line 73, in branch
    raise RuntimeError("client close")
RuntimeError: client close

2019-03-11 19:02:05,612 - ERROR - Service.py[:63] - recv data error exe con.close ,info:Traceback (most recent call last):
  File "/Users/tanjun/it/GitHub/cat08/cat08_websocket/cat08/Service.py", line 59, in run
    msg = self.branch(self.buffer_utf8)
  File "/Users/tanjun/it/GitHub/cat08/cat08_websocket/cat08/Service.py", line 73, in branch
    raise RuntimeError("client close")
RuntimeError: client close

2019-03-11 19:02:51,675 - DEBUG - App.py[:23] - 启动websock,端口是:4397
2019-03-11 19:04:01,886 - DEBUG - App.py[:23] - 启动websock,端口是:4397
2019-03-11 19:04:59,309 - ERROR - Service.py[:63] - recv data error exe con.close ,info:Traceback (most recent call last):
  File "/Users/tanjun/it/GitHub/cat08/cat08_websocket/cat08/Service.py", line 52, in run
    raise RuntimeError("client close")
RuntimeError: client close

2019-03-11 19:05:22,915 - ERROR - Service.py[:63] - recv data error exe con.close ,info:Traceback (most recent call last):
  File "/Users/tanjun/it/GitHub/cat08/cat08_websocket/cat08/Service.py", line 52, in run
    raise RuntimeError("client close")
RuntimeError: client close

2019-03-11 19:07:39,559 - DEBUG - App.py[:23] - 启动websock,端口是:4397
2019-03-11 19:09:58,951 - DEBUG - App.py[:23] - 启动websock,端口是:4397
2019-03-11 19:16:39,799 - DEBUG - App.py[:23] - 启动websock,端口是:4397
2019-03-11 19:19:06,371 - DEBUG - App.py[:23] - 启动websock,端口是:4397
2019-03-11 19:19:26,532 - ERROR - Service.py[:63] - recv data error exe con.close ,info:Traceback (most recent call last):
  File "/Users/tanjun/it/GitHub/cat08/cat08_websocket/cat08/Service.py", line 59, in run
    msg = self.branch(self.buffer_utf8)
  File "/Users/tanjun/it/GitHub/cat08/cat08_websocket/cat08/Service.py", line 90, in branch
    self.branch(nextMsg)
  File "/Users/tanjun/it/GitHub/cat08/cat08_websocket/cat08/Service.py", line 90, in branch
    self.branch(nextMsg)
  File "/Users/tanjun/it/GitHub/cat08/cat08_websocket/cat08/Service.py", line 71, in branch
    msg = Util.t_recvStr(msg)
  File "/Users/tanjun/it/GitHub/cat08/cat08_websocket/cat08/Util.py", line 65, in t_recvStr
    payload_len = ord(info[1]) & 127 #126以内是正确的长度
IndexError: string index out of range

2019-03-11 19:22:07,772 - DEBUG - App.py[:23] - 启动websock,端口是:4397
2019-03-11 19:24:12,150 - DEBUG - App.py[:23] - 启动websock,端口是:4397
2019-03-11 19:28:10,721 - DEBUG - App.py[:23] - 启动websock,端口是:4397
2019-03-11 19:28:33,689 - DEBUG - App.py[:23] - 启动websock,端口是:4397
2019-03-11 19:28:38,127 - ERROR - Service.py[:63] - recv data error exe con.close ,info:Traceback (most recent call last):
  File "/Users/tanjun/it/GitHub/cat08/cat08_websocket/cat08/Service.py", line 59, in run
    msg = self.branch(self.buffer_utf8)
  File "/Users/tanjun/it/GitHub/cat08/cat08_websocket/cat08/Service.py", line 88, in branch
    Util.senOthers(retMsg, self.con)
  File "/Users/tanjun/it/GitHub/cat08/cat08_websocket/cat08/Util.py", line 29, in senOthers
    con.sendall(msg)
  File "/System/Library/Frameworks/Python.framework/Versions/2.7/lib/python2.7/socket.py", line 228, in meth
    return getattr(self._sock,name)(*args)
TypeError: must be string or buffer, not bool

2019-03-11 19:28:39,062 - ERROR - Service.py[:63] - recv data error exe con.close ,info:Traceback (most recent call last):
  File "/Users/tanjun/it/GitHub/cat08/cat08_websocket/cat08/Service.py", line 59, in run
    msg = self.branch(self.buffer_utf8)
  File "/Users/tanjun/it/GitHub/cat08/cat08_websocket/cat08/Service.py", line 88, in branch
    Util.senOthers(retMsg, self.con)
  File "/Users/tanjun/it/GitHub/cat08/cat08_websocket/cat08/Util.py", line 29, in senOthers
    con.sendall(msg)
  File "/System/Library/Frameworks/Python.framework/Versions/2.7/lib/python2.7/socket.py", line 228, in meth
    return getattr(self._sock,name)(*args)
TypeError: must be string or buffer, not bool

2019-03-11 19:30:23,003 - DEBUG - App.py[:23] - 启动websock,端口是:4397
2019-03-11 19:30:26,213 - ERROR - Service.py[:63] - recv data error exe con.close ,info:Traceback (most recent call last):
  File "/Users/tanjun/it/GitHub/cat08/cat08_websocket/cat08/Service.py", line 59, in run
    msg = self.branch(self.buffer_utf8)
  File "/Users/tanjun/it/GitHub/cat08/cat08_websocket/cat08/Service.py", line 73, in branch
    msg = Util.t_recvStr(msg[0:hadelen+1])
  File "/Users/tanjun/it/GitHub/cat08/cat08_websocket/cat08/Util.py", line 75, in t_recvStr
    payload_len = ord(info[1]) & 127 #126以内是正确的长度
IndexError: string index out of range

2019-03-11 19:30:27,003 - ERROR - Service.py[:63] - recv data error exe con.close ,info:Traceback (most recent call last):
  File "/Users/tanjun/it/GitHub/cat08/cat08_websocket/cat08/Service.py", line 59, in run
    msg = self.branch(self.buffer_utf8)
  File "/Users/tanjun/it/GitHub/cat08/cat08_websocket/cat08/Service.py", line 73, in branch
    msg = Util.t_recvStr(msg[0:hadelen+1])
  File "/Users/tanjun/it/GitHub/cat08/cat08_websocket/cat08/Util.py", line 75, in t_recvStr
    payload_len = ord(info[1]) & 127 #126以内是正确的长度
IndexError: string index out of range

2019-03-11 19:30:27,721 - ERROR - Service.py[:63] - recv data error exe con.close ,info:Traceback (most recent call last):
  File "/Users/tanjun/it/GitHub/cat08/cat08_websocket/cat08/Service.py", line 59, in run
    msg = self.branch(self.buffer_utf8)
  File "/Users/tanjun/it/GitHub/cat08/cat08_websocket/cat08/Service.py", line 73, in branch
    msg = Util.t_recvStr(msg[0:hadelen+1])
  File "/Users/tanjun/it/GitHub/cat08/cat08_websocket/cat08/Util.py", line 75, in t_recvStr
    payload_len = ord(info[1]) & 127 #126以内是正确的长度
IndexError: string index out of range

2019-03-11 19:30:27,874 - ERROR - Service.py[:63] - recv data error exe con.close ,info:Traceback (most recent call last):
  File "/Users/tanjun/it/GitHub/cat08/cat08_websocket/cat08/Service.py", line 59, in run
    msg = self.branch(self.buffer_utf8)
  File "/Users/tanjun/it/GitHub/cat08/cat08_websocket/cat08/Service.py", line 73, in branch
    msg = Util.t_recvStr(msg[0:hadelen+1])
  File "/Users/tanjun/it/GitHub/cat08/cat08_websocket/cat08/Util.py", line 75, in t_recvStr
    payload_len = ord(info[1]) & 127 #126以内是正确的长度
IndexError: string index out of range

2019-03-11 19:31:16,285 - DEBUG - App.py[:23] - 启动websock,端口是:4397
2019-03-11 19:31:41,070 - ERROR - Service.py[:63] - recv data error exe con.close ,info:Traceback (most recent call last):
  File "/Users/tanjun/it/GitHub/cat08/cat08_websocket/cat08/Service.py", line 59, in run
    msg = self.branch(self.buffer_utf8)
  File "/Users/tanjun/it/GitHub/cat08/cat08_websocket/cat08/Service.py", line 72, in branch
    msglen = int(Util.t_recvStr(msg[0:hadelen + 5]))
ValueError: invalid literal for int() with base 10: '\x19\x01\x17E]'

2019-03-11 19:34:56,898 - DEBUG - App.py[:23] - 启动websock,端口是:4397
2019-03-11 19:36:15,979 - ERROR - Service.py[:63] - recv data error exe con.close ,info:Traceback (most recent call last):
  File "/Users/tanjun/it/GitHub/cat08/cat08_websocket/cat08/Service.py", line 59, in run
    msg = self.branch(self.buffer_utf8)
  File "/Users/tanjun/it/GitHub/cat08/cat08_websocket/cat08/Service.py", line 72, in branch
    msglen = int(Util.t_recvStr(msg[0:hadelen + 5]))
ValueError: invalid literal for int() with base 10: '\x19\x01\x17E]'

2019-03-11 19:37:06,439 - ERROR - Service.py[:63] - recv data error exe con.close ,info:Traceback (most recent call last):
  File "/Users/tanjun/it/GitHub/cat08/cat08_websocket/cat08/Service.py", line 59, in run
    msg = self.branch(self.buffer_utf8)
  File "/Users/tanjun/it/GitHub/cat08/cat08_websocket/cat08/Service.py", line 72, in branch
    msglen = int(Util.t_recvStr(msg[0:hadelen + 5]))
ValueError: invalid literal for int() with base 10: '\x19\x01\x17E]'

2019-03-11 19:38:25,526 - ERROR - Service.py[:63] - recv data error exe con.close ,info:Traceback (most recent call last):
  File "/Users/tanjun/it/GitHub/cat08/cat08_websocket/cat08/Service.py", line 59, in run
    msg = self.branch(self.buffer_utf8)
  File "/Users/tanjun/it/GitHub/cat08/cat08_websocket/cat08/Service.py", line 72, in branch
    msglen = int(Util.t_recvStr(msg[0:hadelen + 5]))
ValueError: invalid literal for int() with base 10: '\x1a\x0c\x1d\x0fN'

2019-03-11 19:39:08,182 - DEBUG - App.py[:23] - 启动websock,端口是:4397
2019-03-11 19:42:07,069 - DEBUG - App.py[:23] - 启动websock,端口是:4397
2019-03-11 19:42:57,257 - DEBUG - App.py[:23] - 启动websock,端口是:4397
2019-03-11 19:44:07,141 - DEBUG - App.py[:23] - 启动websock,端口是:4397
2019-03-11 19:45:16,273 - ERROR - Service.py[:63] - recv data error exe con.close ,info:Traceback (most recent call last):
  File "/Users/tanjun/it/GitHub/cat08/cat08_websocket/cat08/Service.py", line 52, in run
    raise RuntimeError("client close")
RuntimeError: client close

2019-03-11 19:45:19,224 - ERROR - Service.py[:63] - recv data error exe con.close ,info:Traceback (most recent call last):
  File "/Users/tanjun/it/GitHub/cat08/cat08_websocket/cat08/Service.py", line 52, in run
    raise RuntimeError("client close")
RuntimeError: client close

2019-03-11 19:46:16,248 - ERROR - Service.py[:63] - recv data error exe con.close ,info:Traceback (most recent call last):
  File "/Users/tanjun/it/GitHub/cat08/cat08_websocket/cat08/Service.py", line 52, in run
    raise RuntimeError("client close")
RuntimeError: client close

2019-03-11 19:46:23,460 - ERROR - Service.py[:63] - recv data error exe con.close ,info:Traceback (most recent call last):
  File "/Users/tanjun/it/GitHub/cat08/cat08_websocket/cat08/Service.py", line 52, in run
    raise RuntimeError("client close")
RuntimeError: client close

2019-03-11 19:47:14,035 - DEBUG - App.py[:23] - 启动websock,端口是:4397
2019-03-11 19:49:36,472 - DEBUG - App.py[:23] - 启动websock,端口是:4397
2019-03-11 19:56:05,102 - DEBUG - App.py[:23] - 启动websock,端口是:4397
2019-03-11 19:57:09,584 - ERROR - Service.py[:64] - recv data error exe con.close ,info:Traceback (most recent call last):
  File "/Users/tanjun/it/GitHub/cat08/cat08_websocket/cat08/Service.py", line 52, in run
    raise RuntimeError("client close")
RuntimeError: client close

2019-03-12 14:30:57,378 - DEBUG - App.py[:23] - 启动websock,端口是:4397
2019-03-12 14:31:03,124 - DEBUG - App.py[:23] - 启动websock,端口是:4397
2019-03-12 14:33:12,850 - ERROR - Service.py[:64] - recv data error exe con.close ,info:Traceback (most recent call last):
  File "/Users/tanjun/it/GitHub/cat08/cat08_websocket/cat08/Service.py", line 45, in run
    raise KeyError("websocket key error:" + str(e.message))
KeyError: 'websocket key error:Sec-WebSocket-Key'

2019-03-12 14:33:28,733 - ERROR - Service.py[:64] - recv data error exe con.close ,info:Traceback (most recent call last):
  File "/Users/tanjun/it/GitHub/cat08/cat08_websocket/cat08/Service.py", line 45, in run
    raise KeyError("websocket key error:" + str(e.message))
KeyError: 'websocket key error:Sec-WebSocket-Key'

2019-03-12 14:33:30,109 - ERROR - Service.py[:64] - recv data error exe con.close ,info:Traceback (most recent call last):
  File "/Users/tanjun/it/GitHub/cat08/cat08_websocket/cat08/Service.py", line 45, in run
    raise KeyError("websocket key error:" + str(e.message))
KeyError: 'websocket key error:Sec-WebSocket-Key'

2019-03-12 14:33:45,896 - ERROR - Service.py[:64] - recv data error exe con.close ,info:Traceback (most recent call last):
  File "/Users/tanjun/it/GitHub/cat08/cat08_websocket/cat08/Service.py", line 45, in run
    raise KeyError("websocket key error:" + str(e.message))
KeyError: 'websocket key error:Sec-WebSocket-Key'

2019-03-12 14:33:51,320 - ERROR - Service.py[:64] - recv data error exe con.close ,info:Traceback (most recent call last):
  File "/Users/tanjun/it/GitHub/cat08/cat08_websocket/cat08/Service.py", line 45, in run
    raise KeyError("websocket key error:" + str(e.message))
KeyError: 'websocket key error:Sec-WebSocket-Key'

2019-03-12 14:33:51,980 - ERROR - Service.py[:64] - recv data error exe con.close ,info:Traceback (most recent call last):
  File "/Users/tanjun/it/GitHub/cat08/cat08_websocket/cat08/Service.py", line 45, in run
    raise KeyError("websocket key error:" + str(e.message))
KeyError: 'websocket key error:Sec-WebSocket-Key'

2019-03-12 14:33:52,160 - ERROR - Service.py[:64] - recv data error exe con.close ,info:Traceback (most recent call last):
  File "/Users/tanjun/it/GitHub/cat08/cat08_websocket/cat08/Service.py", line 45, in run
    raise KeyError("websocket key error:" + str(e.message))
KeyError: 'websocket key error:Sec-WebSocket-Key'

2019-03-12 14:34:28,088 - DEBUG - App.py[:23] - 启动websock,端口是:4397
2019-03-12 14:34:32,200 - ERROR - Service.py[:64] - recv data error exe con.close ,info:Traceback (most recent call last):
  File "/Users/tanjun/it/GitHub/cat08/cat08_websocket/cat08/Service.py", line 45, in run
    raise KeyError("websocket key error:" + str(e.message))
KeyError: 'websocket key error:Sec-WebSocket-Key'

2019-03-12 14:34:33,234 - ERROR - Service.py[:64] - recv data error exe con.close ,info:Traceback (most recent call last):
  File "/Users/tanjun/it/GitHub/cat08/cat08_websocket/cat08/Service.py", line 45, in run
    raise KeyError("websocket key error:" + str(e.message))
KeyError: 'websocket key error:Sec-WebSocket-Key'

2019-03-12 14:34:33,409 - ERROR - Service.py[:64] - recv data error exe con.close ,info:Traceback (most recent call last):
  File "/Users/tanjun/it/GitHub/cat08/cat08_websocket/cat08/Service.py", line 45, in run
    raise KeyError("websocket key error:" + str(e.message))
KeyError: 'websocket key error:Sec-WebSocket-Key'

2019-03-12 14:39:28,503 - DEBUG - App.py[:23] - 启动websock,端口是:4397
2019-03-12 14:39:32,385 - ERROR - Service.py[:64] - recv data error exe con.close ,info:Traceback (most recent call last):
  File "/Users/tanjun/it/GitHub/cat08/cat08_websocket/cat08/Service.py", line 45, in run
    raise KeyError("websocket key error:" + str(e.message))
KeyError: 'websocket key error:Sec-WebSocket-Key'

2019-03-12 14:39:33,460 - ERROR - Service.py[:64] - recv data error exe con.close ,info:Traceback (most recent call last):
  File "/Users/tanjun/it/GitHub/cat08/cat08_websocket/cat08/Service.py", line 45, in run
    raise KeyError("websocket key error:" + str(e.message))
KeyError: 'websocket key error:Sec-WebSocket-Key'

2019-03-12 14:39:33,613 - ERROR - Service.py[:64] - recv data error exe con.close ,info:Traceback (most recent call last):
  File "/Users/tanjun/it/GitHub/cat08/cat08_websocket/cat08/Service.py", line 45, in run
    raise KeyError("websocket key error:" + str(e.message))
KeyError: 'websocket key error:Sec-WebSocket-Key'

2019-03-12 14:40:05,781 - DEBUG - App.py[:23] - 启动websock,端口是:4397
2019-03-12 14:40:37,010 - ERROR - Service.py[:64] - recv data error exe con.close ,info:Traceback (most recent call last):
  File "/Users/tanjun/it/GitHub/cat08/cat08_websocket/cat08/Service.py", line 45, in run
    raise KeyError("websocket key error:" + str(e.message))
KeyError: 'websocket key error:Sec-WebSocket-Key'

2019-03-12 14:40:37,680 - ERROR - Service.py[:64] - recv data error exe con.close ,info:Traceback (most recent call last):
  File "/Users/tanjun/it/GitHub/cat08/cat08_websocket/cat08/Service.py", line 45, in run
    raise KeyError("websocket key error:" + str(e.message))
KeyError: 'websocket key error:Sec-WebSocket-Key'

2019-03-12 14:40:37,834 - ERROR - Service.py[:64] - recv data error exe con.close ,info:Traceback (most recent call last):
  File "/Users/tanjun/it/GitHub/cat08/cat08_websocket/cat08/Service.py", line 45, in run
    raise KeyError("websocket key error:" + str(e.message))
KeyError: 'websocket key error:Sec-WebSocket-Key'

2019-03-12 14:42:23,568 - ERROR - Service.py[:64] - recv data error exe con.close ,info:Traceback (most recent call last):
  File "/Users/tanjun/it/GitHub/cat08/cat08_websocket/cat08/Service.py", line 45, in run
    raise KeyError("websocket key error:" + str(e.message))
KeyError: 'websocket key error:Sec-WebSocket-Key'

2019-03-12 14:42:24,464 - ERROR - Service.py[:64] - recv data error exe con.close ,info:Traceback (most recent call last):
  File "/Users/tanjun/it/GitHub/cat08/cat08_websocket/cat08/Service.py", line 45, in run
    raise KeyError("websocket key error:" + str(e.message))
KeyError: 'websocket key error:Sec-WebSocket-Key'

2019-03-12 14:42:24,647 - ERROR - Service.py[:64] - recv data error exe con.close ,info:Traceback (most recent call last):
  File "/Users/tanjun/it/GitHub/cat08/cat08_websocket/cat08/Service.py", line 45, in run
    raise KeyError("websocket key error:" + str(e.message))
KeyError: 'websocket key error:Sec-WebSocket-Key'

2019-03-12 14:45:28,457 - DEBUG - App.py[:23] - 启动websock,端口是:4397
2019-03-12 14:46:26,515 - ERROR - Service.py[:64] - recv data error exe con.close ,info:Traceback (most recent call last):
  File "/Users/tanjun/it/GitHub/cat08/cat08_websocket/cat08/Service.py", line 52, in run
    raise RuntimeError("client close")
RuntimeError: client close

2019-03-12 14:47:04,312 - DEBUG - App.py[:23] - 启动websock,端口是:4397
2019-03-12 14:49:18,252 - DEBUG - App.py[:23] - 启动websock,端口是:4397
2019-03-12 14:53:40,471 - DEBUG - App.py[:23] - 启动websock,端口是:4397
2019-03-12 14:56:47,454 - ERROR - Service.py[:64] - recv data error exe con.close ,info:Traceback (most recent call last):
  File "/Users/tanjun/it/GitHub/cat08/cat08_websocket/cat08/Service.py", line 52, in run
    raise RuntimeError("client close")
RuntimeError: client close

2019-03-12 15:01:44,567 - DEBUG - App.py[:23] - 启动websock,端口是:4397
2019-03-12 15:02:12,078 - ERROR - Service.py[:64] - recv data error exe con.close ,info:Traceback (most recent call last):
  File "/Users/tanjun/it/GitHub/cat08/cat08_websocket/cat08/Service.py", line 52, in run
    raise RuntimeError("client close")
RuntimeError: client close

2019-03-12 15:03:27,922 - ERROR - Service.py[:64] - recv data error exe con.close ,info:Traceback (most recent call last):
  File "/Users/tanjun/it/GitHub/cat08/cat08_websocket/cat08/Service.py", line 52, in run
    raise RuntimeError("client close")
RuntimeError: client close

2019-03-12 15:03:28,655 - ERROR - Service.py[:64] - recv data error exe con.close ,info:Traceback (most recent call last):
  File "/Users/tanjun/it/GitHub/cat08/cat08_websocket/cat08/Service.py", line 52, in run
    raise RuntimeError("client close")
RuntimeError: client close

